# coding: utf-8

from datetime import date, datetime

from typing import List, Dict, Type

from openapi_server.models.base_model import Model
from openapi_server import util


class PullDocumentId404Response(Model):
    """NOTE: This class is auto generated by OpenAPI Generator (https://openapi-generator.tech).

    Do not edit the class manually.
    """

    def __init__(self, error: object=None, error_description: object=None):
        """PullDocumentId404Response - a model defined in OpenAPI

        :param error: The error of this PullDocumentId404Response.
        :param error_description: The error_description of this PullDocumentId404Response.
        """
        self.openapi_types = {
            'error': object,
            'error_description': object
        }

        self.attribute_map = {
            'error': 'error',
            'error_description': 'error_description'
        }

        self._error = error
        self._error_description = error_description

    @classmethod
    def from_dict(cls, dikt: dict) -> 'PullDocumentId404Response':
        """Returns the dict as a model

        :param dikt: A dict.
        :return: The Pull_Document_id_404_response of this PullDocumentId404Response.
        """
        return util.deserialize_model(dikt, cls)

    @property
    def error(self):
        """Gets the error of this PullDocumentId404Response.

        record_not_found

        :return: The error of this PullDocumentId404Response.
        :rtype: object
        """
        return self._error

    @error.setter
    def error(self, error):
        """Sets the error of this PullDocumentId404Response.

        record_not_found

        :param error: The error of this PullDocumentId404Response.
        :type error: object
        """

        self._error = error

    @property
    def error_description(self):
        """Gets the error_description of this PullDocumentId404Response.

        No record found in issuer database for given criteria. Please check the details and try again. If problem persists, see the FAQ section for possible causes.

        :return: The error_description of this PullDocumentId404Response.
        :rtype: object
        """
        return self._error_description

    @error_description.setter
    def error_description(self, error_description):
        """Sets the error_description of this PullDocumentId404Response.

        No record found in issuer database for given criteria. Please check the details and try again. If problem persists, see the FAQ section for possible causes.

        :param error_description: The error_description of this PullDocumentId404Response.
        :type error_description: object
        """

        self._error_description = error_description
